[2024-08-11T08:38:27.215+0000] {local_task_job_runner.py:120} INFO - ::group::Pre task execution logs
[2024-08-11T08:38:27.248+0000] {taskinstance.py:2076} INFO - Dependencies all met for dep_context=non-requeueable deps ti=<TaskInstance: Zillow_Analytics_DAG.load_to_s3_bucket_zillowapibucket manual__2024-08-11T08:37:59.044105+00:00 [queued]>
[2024-08-11T08:38:27.253+0000] {taskinstance.py:2076} INFO - Dependencies all met for dep_context=requeueable deps ti=<TaskInstance: Zillow_Analytics_DAG.load_to_s3_bucket_zillowapibucket manual__2024-08-11T08:37:59.044105+00:00 [queued]>
[2024-08-11T08:38:27.253+0000] {taskinstance.py:2306} INFO - Starting attempt 2 of 3
[2024-08-11T08:38:27.270+0000] {taskinstance.py:2330} INFO - Executing <Task(BashOperator): load_to_s3_bucket_zillowapibucket> on 2024-08-11 08:37:59.044105+00:00
[2024-08-11T08:38:27.273+0000] {standard_task_runner.py:64} INFO - Started process 3576 to run task
[2024-08-11T08:38:27.275+0000] {standard_task_runner.py:90} INFO - Running: ['airflow', 'tasks', 'run', 'Zillow_Analytics_DAG', 'load_to_s3_bucket_zillowapibucket', 'manual__2024-08-11T08:37:59.044105+00:00', '--job-id', '12', '--raw', '--subdir', 'DAGS_FOLDER/zillowrapidapi.py', '--cfg-path', '/tmp/tmp4h7wx4tc']
[2024-08-11T08:38:27.276+0000] {standard_task_runner.py:91} INFO - Job 12: Subtask load_to_s3_bucket_zillowapibucket
[2024-08-11T08:38:27.310+0000] {task_command.py:426} INFO - Running <TaskInstance: Zillow_Analytics_DAG.load_to_s3_bucket_zillowapibucket manual__2024-08-11T08:37:59.044105+00:00 [running]> on host ip-172-31-11-55.ap-south-1.compute.internal
[2024-08-11T08:38:27.366+0000] {taskinstance.py:2648} INFO - Exporting env vars: AIRFLOW_CTX_DAG_EMAIL='vkkr800@gmail.com' AIRFLOW_CTX_DAG_OWNER='airflow' AIRFLOW_CTX_DAG_ID='Zillow_Analytics_DAG' AIRFLOW_CTX_TASK_ID='load_to_s3_bucket_zillowapibucket' AIRFLOW_CTX_EXECUTION_DATE='2024-08-11T08:37:59.044105+00:00' AIRFLOW_CTX_TRY_NUMBER='2' AIRFLOW_CTX_DAG_RUN_ID='manual__2024-08-11T08:37:59.044105+00:00'
[2024-08-11T08:38:27.367+0000] {taskinstance.py:430} INFO - ::endgroup::
[2024-08-11T08:38:27.377+0000] {subprocess.py:63} INFO - Tmp dir root location: /tmp
[2024-08-11T08:38:27.378+0000] {subprocess.py:75} INFO - Running command: ['/usr/bin/bash', '-c', 'aws s3 mv /home/ubuntu/response_data_11082024083804.json s3://zillow-api-bucket-1st/']
[2024-08-11T08:38:27.384+0000] {subprocess.py:86} INFO - Output:
[2024-08-11T08:38:27.812+0000] {subprocess.py:93} INFO - move failed: ../../home/ubuntu/response_data_11082024083804.json to s3://zillow-api-bucket-1st/response_data_11082024083804.json Unable to locate credentials
[2024-08-11T08:38:27.873+0000] {subprocess.py:97} INFO - Command exited with return code 1
[2024-08-11T08:38:27.874+0000] {taskinstance.py:441} INFO - ::group::Post task execution logs
[2024-08-11T08:38:27.880+0000] {taskinstance.py:2905} ERROR - Task failed with exception
Traceback (most recent call last):
  File "/home/ubuntu/zilloapi/lib/python3.12/site-packages/airflow/models/taskinstance.py", line 465, in _execute_task
    result = _execute_callable(context=context, **execute_callable_kwargs)
             ^^^^^^^^^^^^^^^^^^^^^^^^^^^^^^^^^^^^^^^^^^^^^^^^^^^^^^^^^^^^^
  File "/home/ubuntu/zilloapi/lib/python3.12/site-packages/airflow/models/taskinstance.py", line 432, in _execute_callable
    return execute_callable(context=context, **execute_callable_kwargs)
           ^^^^^^^^^^^^^^^^^^^^^^^^^^^^^^^^^^^^^^^^^^^^^^^^^^^^^^^^^^^^
  File "/home/ubuntu/zilloapi/lib/python3.12/site-packages/airflow/models/baseoperator.py", line 401, in wrapper
    return func(self, *args, **kwargs)
           ^^^^^^^^^^^^^^^^^^^^^^^^^^^
  File "/home/ubuntu/zilloapi/lib/python3.12/site-packages/airflow/operators/bash.py", line 243, in execute
    raise AirflowException(
airflow.exceptions.AirflowException: Bash command failed. The command returned a non-zero exit code 1.
[2024-08-11T08:38:27.883+0000] {taskinstance.py:1206} INFO - Marking task as UP_FOR_RETRY. dag_id=Zillow_Analytics_DAG, task_id=load_to_s3_bucket_zillowapibucket, run_id=manual__2024-08-11T08:37:59.044105+00:00, execution_date=20240811T083759, start_date=20240811T083827, end_date=20240811T083827
[2024-08-11T08:38:27.899+0000] {standard_task_runner.py:110} ERROR - Failed to execute job 12 for task load_to_s3_bucket_zillowapibucket (Bash command failed. The command returned a non-zero exit code 1.; 3576)
[2024-08-11T08:38:27.932+0000] {local_task_job_runner.py:243} INFO - Task exited with return code 1
[2024-08-11T08:38:27.942+0000] {taskinstance.py:3503} INFO - 0 downstream tasks scheduled from follow-on schedule check
[2024-08-11T08:38:27.943+0000] {local_task_job_runner.py:222} INFO - ::endgroup::
