[2024-08-11T08:50:13.201+0000] {local_task_job_runner.py:120} INFO - ::group::Pre task execution logs
[2024-08-11T08:50:13.217+0000] {taskinstance.py:2076} INFO - Dependencies all met for dep_context=non-requeueable deps ti=<TaskInstance: Zillow_Analytics_DAG.load_to_s3_bucket_zillowapibucket manual__2024-08-11T08:37:59.044105+00:00 [queued]>
[2024-08-11T08:50:13.223+0000] {taskinstance.py:2076} INFO - Dependencies all met for dep_context=requeueable deps ti=<TaskInstance: Zillow_Analytics_DAG.load_to_s3_bucket_zillowapibucket manual__2024-08-11T08:37:59.044105+00:00 [queued]>
[2024-08-11T08:50:13.223+0000] {taskinstance.py:2306} INFO - Starting attempt 8 of 9
[2024-08-11T08:50:13.239+0000] {taskinstance.py:2330} INFO - Executing <Task(BashOperator): load_to_s3_bucket_zillowapibucket> on 2024-08-11 08:37:59.044105+00:00
[2024-08-11T08:50:13.241+0000] {standard_task_runner.py:64} INFO - Started process 3721 to run task
[2024-08-11T08:50:13.244+0000] {standard_task_runner.py:90} INFO - Running: ['airflow', 'tasks', 'run', 'Zillow_Analytics_DAG', 'load_to_s3_bucket_zillowapibucket', 'manual__2024-08-11T08:37:59.044105+00:00', '--job-id', '21', '--raw', '--subdir', 'DAGS_FOLDER/zillowrapidapi.py', '--cfg-path', '/tmp/tmpdqq34prx']
[2024-08-11T08:50:13.246+0000] {standard_task_runner.py:91} INFO - Job 21: Subtask load_to_s3_bucket_zillowapibucket
[2024-08-11T08:50:13.282+0000] {task_command.py:426} INFO - Running <TaskInstance: Zillow_Analytics_DAG.load_to_s3_bucket_zillowapibucket manual__2024-08-11T08:37:59.044105+00:00 [running]> on host ip-172-31-11-55.ap-south-1.compute.internal
[2024-08-11T08:50:13.342+0000] {taskinstance.py:2648} INFO - Exporting env vars: AIRFLOW_CTX_DAG_EMAIL='vkkr800@gmail.com' AIRFLOW_CTX_DAG_OWNER='airflow' AIRFLOW_CTX_DAG_ID='Zillow_Analytics_DAG' AIRFLOW_CTX_TASK_ID='load_to_s3_bucket_zillowapibucket' AIRFLOW_CTX_EXECUTION_DATE='2024-08-11T08:37:59.044105+00:00' AIRFLOW_CTX_TRY_NUMBER='8' AIRFLOW_CTX_DAG_RUN_ID='manual__2024-08-11T08:37:59.044105+00:00'
[2024-08-11T08:50:13.344+0000] {taskinstance.py:430} INFO - ::endgroup::
[2024-08-11T08:50:13.354+0000] {subprocess.py:63} INFO - Tmp dir root location: /tmp
[2024-08-11T08:50:13.354+0000] {subprocess.py:75} INFO - Running command: ['/usr/bin/bash', '-c', 'aws s3 mv /home/ubuntu/response_data_11082024084951.json s3://zillow-api-bucket-1st/']
[2024-08-11T08:50:13.361+0000] {subprocess.py:86} INFO - Output:
[2024-08-11T08:50:13.805+0000] {subprocess.py:93} INFO - move failed: ../../home/ubuntu/response_data_11082024084951.json to s3://zillow-api-bucket-1st/response_data_11082024084951.json Unable to locate credentials
[2024-08-11T08:50:13.868+0000] {subprocess.py:97} INFO - Command exited with return code 1
[2024-08-11T08:50:13.869+0000] {taskinstance.py:441} INFO - ::group::Post task execution logs
[2024-08-11T08:50:13.874+0000] {taskinstance.py:2905} ERROR - Task failed with exception
Traceback (most recent call last):
  File "/home/ubuntu/zilloapi/lib/python3.12/site-packages/airflow/models/taskinstance.py", line 465, in _execute_task
    result = _execute_callable(context=context, **execute_callable_kwargs)
             ^^^^^^^^^^^^^^^^^^^^^^^^^^^^^^^^^^^^^^^^^^^^^^^^^^^^^^^^^^^^^
  File "/home/ubuntu/zilloapi/lib/python3.12/site-packages/airflow/models/taskinstance.py", line 432, in _execute_callable
    return execute_callable(context=context, **execute_callable_kwargs)
           ^^^^^^^^^^^^^^^^^^^^^^^^^^^^^^^^^^^^^^^^^^^^^^^^^^^^^^^^^^^^
  File "/home/ubuntu/zilloapi/lib/python3.12/site-packages/airflow/models/baseoperator.py", line 401, in wrapper
    return func(self, *args, **kwargs)
           ^^^^^^^^^^^^^^^^^^^^^^^^^^^
  File "/home/ubuntu/zilloapi/lib/python3.12/site-packages/airflow/operators/bash.py", line 243, in execute
    raise AirflowException(
airflow.exceptions.AirflowException: Bash command failed. The command returned a non-zero exit code 1.
[2024-08-11T08:50:13.878+0000] {taskinstance.py:1206} INFO - Marking task as UP_FOR_RETRY. dag_id=Zillow_Analytics_DAG, task_id=load_to_s3_bucket_zillowapibucket, run_id=manual__2024-08-11T08:37:59.044105+00:00, execution_date=20240811T083759, start_date=20240811T085013, end_date=20240811T085013
[2024-08-11T08:50:13.892+0000] {standard_task_runner.py:110} ERROR - Failed to execute job 21 for task load_to_s3_bucket_zillowapibucket (Bash command failed. The command returned a non-zero exit code 1.; 3721)
[2024-08-11T08:50:13.899+0000] {local_task_job_runner.py:243} INFO - Task exited with return code 1
[2024-08-11T08:50:13.908+0000] {taskinstance.py:3503} INFO - 0 downstream tasks scheduled from follow-on schedule check
[2024-08-11T08:50:13.909+0000] {local_task_job_runner.py:222} INFO - ::endgroup::
