[2024-08-11T13:33:58.449+0000] {local_task_job_runner.py:120} INFO - ::group::Pre task execution logs
[2024-08-11T13:33:58.459+0000] {taskinstance.py:2076} INFO - Dependencies all met for dep_context=non-requeueable deps ti=<TaskInstance: Zillow_Analytics_DAG.is_file_in_s3 manual__2024-08-11T13:29:06.027020+00:00 [queued]>
[2024-08-11T13:33:58.464+0000] {taskinstance.py:2076} INFO - Dependencies all met for dep_context=requeueable deps ti=<TaskInstance: Zillow_Analytics_DAG.is_file_in_s3 manual__2024-08-11T13:29:06.027020+00:00 [queued]>
[2024-08-11T13:33:58.465+0000] {taskinstance.py:2306} INFO - Starting attempt 1 of 3
[2024-08-11T13:33:58.484+0000] {taskinstance.py:2330} INFO - Executing <Task(S3KeySensor): is_file_in_s3> on 2024-08-11 13:29:06.027020+00:00
[2024-08-11T13:33:58.488+0000] {standard_task_runner.py:64} INFO - Started process 6959 to run task
[2024-08-11T13:33:58.491+0000] {standard_task_runner.py:90} INFO - Running: ['airflow', 'tasks', 'run', 'Zillow_Analytics_DAG', 'is_file_in_s3', 'manual__2024-08-11T13:29:06.027020+00:00', '--job-id', '79', '--raw', '--subdir', 'DAGS_FOLDER/zillowrapidapi.py', '--cfg-path', '/tmp/tmpyo1rp7fa']
[2024-08-11T13:33:58.492+0000] {standard_task_runner.py:91} INFO - Job 79: Subtask is_file_in_s3
[2024-08-11T13:33:58.525+0000] {task_command.py:426} INFO - Running <TaskInstance: Zillow_Analytics_DAG.is_file_in_s3 manual__2024-08-11T13:29:06.027020+00:00 [running]> on host ip-172-31-11-55.ap-south-1.compute.internal
[2024-08-11T13:33:58.597+0000] {taskinstance.py:2648} INFO - Exporting env vars: AIRFLOW_CTX_DAG_EMAIL='vkkr800@gmail.com' AIRFLOW_CTX_DAG_OWNER='airflow' AIRFLOW_CTX_DAG_ID='Zillow_Analytics_DAG' AIRFLOW_CTX_TASK_ID='is_file_in_s3' AIRFLOW_CTX_EXECUTION_DATE='2024-08-11T13:29:06.027020+00:00' AIRFLOW_CTX_TRY_NUMBER='1' AIRFLOW_CTX_DAG_RUN_ID='manual__2024-08-11T13:29:06.027020+00:00'
[2024-08-11T13:33:58.598+0000] {taskinstance.py:430} INFO - ::endgroup::
[2024-08-11T13:33:58.608+0000] {baseoperator.py:400} WARNING - S3KeySensor.execute cannot be called outside TaskInstance!
[2024-08-11T13:33:58.608+0000] {s3.py:118} INFO - Poking for key : s3://zillow-api-third-bucket//home/ubuntu/response_data_11082024133246.json
[2024-08-11T13:33:58.613+0000] {base.py:84} INFO - Using connection ID 'aws_s3_conn' for task execution.
[2024-08-11T13:33:58.613+0000] {connection_wrapper.py:388} INFO - AWS Connection (conn_id='aws_s3_conn', conn_type='aws') credentials retrieved from login and password.
[2024-08-11T13:34:03.937+0000] {s3.py:118} INFO - Poking for key : s3://zillow-api-third-bucket//home/ubuntu/response_data_11082024133246.json
[2024-08-11T13:34:08.949+0000] {s3.py:118} INFO - Poking for key : s3://zillow-api-third-bucket//home/ubuntu/response_data_11082024133246.json
[2024-08-11T13:34:13.957+0000] {s3.py:118} INFO - Poking for key : s3://zillow-api-third-bucket//home/ubuntu/response_data_11082024133246.json
[2024-08-11T13:34:18.965+0000] {s3.py:118} INFO - Poking for key : s3://zillow-api-third-bucket//home/ubuntu/response_data_11082024133246.json
[2024-08-11T13:34:23.973+0000] {s3.py:118} INFO - Poking for key : s3://zillow-api-third-bucket//home/ubuntu/response_data_11082024133246.json
[2024-08-11T13:34:28.981+0000] {s3.py:118} INFO - Poking for key : s3://zillow-api-third-bucket//home/ubuntu/response_data_11082024133246.json
[2024-08-11T13:34:33.990+0000] {s3.py:118} INFO - Poking for key : s3://zillow-api-third-bucket//home/ubuntu/response_data_11082024133246.json
[2024-08-11T13:34:39.000+0000] {s3.py:118} INFO - Poking for key : s3://zillow-api-third-bucket//home/ubuntu/response_data_11082024133246.json
[2024-08-11T13:34:44.009+0000] {s3.py:118} INFO - Poking for key : s3://zillow-api-third-bucket//home/ubuntu/response_data_11082024133246.json
[2024-08-11T13:34:49.020+0000] {s3.py:118} INFO - Poking for key : s3://zillow-api-third-bucket//home/ubuntu/response_data_11082024133246.json
[2024-08-11T13:34:54.027+0000] {s3.py:118} INFO - Poking for key : s3://zillow-api-third-bucket//home/ubuntu/response_data_11082024133246.json
[2024-08-11T13:34:59.038+0000] {s3.py:118} INFO - Poking for key : s3://zillow-api-third-bucket//home/ubuntu/response_data_11082024133246.json
[2024-08-11T13:34:59.047+0000] {taskinstance.py:441} INFO - ::group::Post task execution logs
[2024-08-11T13:34:59.047+0000] {taskinstance.py:2905} ERROR - Task failed with exception
Traceback (most recent call last):
  File "/home/ubuntu/zilloapi/lib/python3.12/site-packages/airflow/models/taskinstance.py", line 465, in _execute_task
    result = _execute_callable(context=context, **execute_callable_kwargs)
             ^^^^^^^^^^^^^^^^^^^^^^^^^^^^^^^^^^^^^^^^^^^^^^^^^^^^^^^^^^^^^
  File "/home/ubuntu/zilloapi/lib/python3.12/site-packages/airflow/models/taskinstance.py", line 432, in _execute_callable
    return execute_callable(context=context, **execute_callable_kwargs)
           ^^^^^^^^^^^^^^^^^^^^^^^^^^^^^^^^^^^^^^^^^^^^^^^^^^^^^^^^^^^^
  File "/home/ubuntu/zilloapi/lib/python3.12/site-packages/airflow/models/baseoperator.py", line 401, in wrapper
    return func(self, *args, **kwargs)
           ^^^^^^^^^^^^^^^^^^^^^^^^^^^
  File "/home/ubuntu/zilloapi/lib/python3.12/site-packages/airflow/providers/amazon/aws/sensors/s3.py", line 189, in execute
    super().execute(context)
  File "/home/ubuntu/zilloapi/lib/python3.12/site-packages/airflow/models/baseoperator.py", line 401, in wrapper
    return func(self, *args, **kwargs)
           ^^^^^^^^^^^^^^^^^^^^^^^^^^^
  File "/home/ubuntu/zilloapi/lib/python3.12/site-packages/airflow/sensors/base.py", line 281, in execute
    raise AirflowSensorTimeout(message)
airflow.exceptions.AirflowSensorTimeout: Sensor has timed out; run duration of 60.43893236200165 seconds exceeds the specified timeout of 60.0.
[2024-08-11T13:34:59.050+0000] {taskinstance.py:1206} INFO - Immediate failure requested. Marking task as FAILED. dag_id=Zillow_Analytics_DAG, task_id=is_file_in_s3, run_id=manual__2024-08-11T13:29:06.027020+00:00, execution_date=20240811T132906, start_date=20240811T133358, end_date=20240811T133459
[2024-08-11T13:34:59.058+0000] {standard_task_runner.py:110} ERROR - Failed to execute job 79 for task is_file_in_s3 ((sqlite3.IntegrityError) FOREIGN KEY constraint failed
[SQL: INSERT INTO task_fail (task_id, dag_id, run_id, map_index, start_date, end_date, duration) VALUES (?, ?, ?, ?, ?, ?, ?)]
[parameters: ('is_file_in_s3', 'Zillow_Analytics_DAG', 'manual__2024-08-11T13:29:06.027020+00:00', -1, '2024-08-11 13:33:58.460125', '2024-08-11 13:34:59.050483', 60)]
(Background on this error at: https://sqlalche.me/e/14/gkpj); 6959)
[2024-08-11T13:34:59.080+0000] {local_task_job_runner.py:243} INFO - Task exited with return code 1
[2024-08-11T13:34:59.084+0000] {local_task_job_runner.py:222} INFO - ::endgroup::
