[2024-08-11T13:36:15.914+0000] {local_task_job_runner.py:120} INFO - ::group::Pre task execution logs
[2024-08-11T13:36:15.924+0000] {taskinstance.py:2076} INFO - Dependencies all met for dep_context=non-requeueable deps ti=<TaskInstance: Zillow_Analytics_DAG.is_file_in_s3 manual__2024-08-11T13:35:02.406578+00:00 [queued]>
[2024-08-11T13:36:15.930+0000] {taskinstance.py:2076} INFO - Dependencies all met for dep_context=requeueable deps ti=<TaskInstance: Zillow_Analytics_DAG.is_file_in_s3 manual__2024-08-11T13:35:02.406578+00:00 [queued]>
[2024-08-11T13:36:15.930+0000] {taskinstance.py:2306} INFO - Starting attempt 1 of 3
[2024-08-11T13:36:15.945+0000] {taskinstance.py:2330} INFO - Executing <Task(S3KeySensor): is_file_in_s3> on 2024-08-11 13:35:02.406578+00:00
[2024-08-11T13:36:15.948+0000] {standard_task_runner.py:64} INFO - Started process 6989 to run task
[2024-08-11T13:36:15.952+0000] {standard_task_runner.py:90} INFO - Running: ['airflow', 'tasks', 'run', 'Zillow_Analytics_DAG', 'is_file_in_s3', 'manual__2024-08-11T13:35:02.406578+00:00', '--job-id', '85', '--raw', '--subdir', 'DAGS_FOLDER/zillowrapidapi.py', '--cfg-path', '/tmp/tmp3y410ud8']
[2024-08-11T13:36:15.953+0000] {standard_task_runner.py:91} INFO - Job 85: Subtask is_file_in_s3
[2024-08-11T13:36:15.986+0000] {task_command.py:426} INFO - Running <TaskInstance: Zillow_Analytics_DAG.is_file_in_s3 manual__2024-08-11T13:35:02.406578+00:00 [running]> on host ip-172-31-11-55.ap-south-1.compute.internal
[2024-08-11T13:36:16.058+0000] {taskinstance.py:2648} INFO - Exporting env vars: AIRFLOW_CTX_DAG_EMAIL='vkkr800@gmail.com' AIRFLOW_CTX_DAG_OWNER='airflow' AIRFLOW_CTX_DAG_ID='Zillow_Analytics_DAG' AIRFLOW_CTX_TASK_ID='is_file_in_s3' AIRFLOW_CTX_EXECUTION_DATE='2024-08-11T13:35:02.406578+00:00' AIRFLOW_CTX_TRY_NUMBER='1' AIRFLOW_CTX_DAG_RUN_ID='manual__2024-08-11T13:35:02.406578+00:00'
[2024-08-11T13:36:16.058+0000] {taskinstance.py:430} INFO - ::endgroup::
[2024-08-11T13:36:16.070+0000] {baseoperator.py:400} WARNING - S3KeySensor.execute cannot be called outside TaskInstance!
[2024-08-11T13:36:16.071+0000] {s3.py:118} INFO - Poking for key : s3://zillow-api-third-bucket//home/ubuntu/response_data_11082024133504.json
[2024-08-11T13:36:16.077+0000] {base.py:84} INFO - Using connection ID 'aws_s3_conn' for task execution.
[2024-08-11T13:36:16.077+0000] {connection_wrapper.py:388} INFO - AWS Connection (conn_id='aws_s3_conn', conn_type='aws') credentials retrieved from login and password.
[2024-08-11T13:36:21.407+0000] {s3.py:118} INFO - Poking for key : s3://zillow-api-third-bucket//home/ubuntu/response_data_11082024133504.json
[2024-08-11T13:36:26.417+0000] {s3.py:118} INFO - Poking for key : s3://zillow-api-third-bucket//home/ubuntu/response_data_11082024133504.json
[2024-08-11T13:36:31.427+0000] {s3.py:118} INFO - Poking for key : s3://zillow-api-third-bucket//home/ubuntu/response_data_11082024133504.json
[2024-08-11T13:36:36.439+0000] {s3.py:118} INFO - Poking for key : s3://zillow-api-third-bucket//home/ubuntu/response_data_11082024133504.json
[2024-08-11T13:36:41.447+0000] {s3.py:118} INFO - Poking for key : s3://zillow-api-third-bucket//home/ubuntu/response_data_11082024133504.json
[2024-08-11T13:36:46.464+0000] {s3.py:118} INFO - Poking for key : s3://zillow-api-third-bucket//home/ubuntu/response_data_11082024133504.json
[2024-08-11T13:36:51.474+0000] {s3.py:118} INFO - Poking for key : s3://zillow-api-third-bucket//home/ubuntu/response_data_11082024133504.json
[2024-08-11T13:36:56.482+0000] {s3.py:118} INFO - Poking for key : s3://zillow-api-third-bucket//home/ubuntu/response_data_11082024133504.json
[2024-08-11T13:37:01.492+0000] {s3.py:118} INFO - Poking for key : s3://zillow-api-third-bucket//home/ubuntu/response_data_11082024133504.json
[2024-08-11T13:37:06.501+0000] {s3.py:118} INFO - Poking for key : s3://zillow-api-third-bucket//home/ubuntu/response_data_11082024133504.json
[2024-08-11T13:37:11.510+0000] {s3.py:118} INFO - Poking for key : s3://zillow-api-third-bucket//home/ubuntu/response_data_11082024133504.json
[2024-08-11T13:37:16.520+0000] {s3.py:118} INFO - Poking for key : s3://zillow-api-third-bucket//home/ubuntu/response_data_11082024133504.json
[2024-08-11T13:37:16.529+0000] {taskinstance.py:441} INFO - ::group::Post task execution logs
[2024-08-11T13:37:16.529+0000] {taskinstance.py:2905} ERROR - Task failed with exception
Traceback (most recent call last):
  File "/home/ubuntu/zilloapi/lib/python3.12/site-packages/airflow/models/taskinstance.py", line 465, in _execute_task
    result = _execute_callable(context=context, **execute_callable_kwargs)
             ^^^^^^^^^^^^^^^^^^^^^^^^^^^^^^^^^^^^^^^^^^^^^^^^^^^^^^^^^^^^^
  File "/home/ubuntu/zilloapi/lib/python3.12/site-packages/airflow/models/taskinstance.py", line 432, in _execute_callable
    return execute_callable(context=context, **execute_callable_kwargs)
           ^^^^^^^^^^^^^^^^^^^^^^^^^^^^^^^^^^^^^^^^^^^^^^^^^^^^^^^^^^^^
  File "/home/ubuntu/zilloapi/lib/python3.12/site-packages/airflow/models/baseoperator.py", line 401, in wrapper
    return func(self, *args, **kwargs)
           ^^^^^^^^^^^^^^^^^^^^^^^^^^^
  File "/home/ubuntu/zilloapi/lib/python3.12/site-packages/airflow/providers/amazon/aws/sensors/s3.py", line 189, in execute
    super().execute(context)
  File "/home/ubuntu/zilloapi/lib/python3.12/site-packages/airflow/models/baseoperator.py", line 401, in wrapper
    return func(self, *args, **kwargs)
           ^^^^^^^^^^^^^^^^^^^^^^^^^^^
  File "/home/ubuntu/zilloapi/lib/python3.12/site-packages/airflow/sensors/base.py", line 281, in execute
    raise AirflowSensorTimeout(message)
airflow.exceptions.AirflowSensorTimeout: Sensor has timed out; run duration of 60.458173401999375 seconds exceeds the specified timeout of 60.0.
[2024-08-11T13:37:16.533+0000] {taskinstance.py:1206} INFO - Immediate failure requested. Marking task as FAILED. dag_id=Zillow_Analytics_DAG, task_id=is_file_in_s3, run_id=manual__2024-08-11T13:35:02.406578+00:00, execution_date=20240811T133502, start_date=20240811T133615, end_date=20240811T133716
[2024-08-11T13:37:16.546+0000] {standard_task_runner.py:110} ERROR - Failed to execute job 85 for task is_file_in_s3 (Sensor has timed out; run duration of 60.458173401999375 seconds exceeds the specified timeout of 60.0.; 6989)
[2024-08-11T13:37:16.587+0000] {local_task_job_runner.py:243} INFO - Task exited with return code 1
[2024-08-11T13:37:16.595+0000] {taskinstance.py:3503} INFO - 0 downstream tasks scheduled from follow-on schedule check
[2024-08-11T13:37:16.595+0000] {local_task_job_runner.py:222} INFO - ::endgroup::
