[2024-08-11T12:41:31.964+0000] {local_task_job_runner.py:120} INFO - ::group::Pre task execution logs
[2024-08-11T12:41:31.973+0000] {taskinstance.py:2076} INFO - Dependencies all met for dep_context=non-requeueable deps ti=<TaskInstance: Zillow_Analytics_DAG.is_file_in_s3 manual__2024-08-11T12:41:22.952529+00:00 [queued]>
[2024-08-11T12:41:31.979+0000] {taskinstance.py:2076} INFO - Dependencies all met for dep_context=requeueable deps ti=<TaskInstance: Zillow_Analytics_DAG.is_file_in_s3 manual__2024-08-11T12:41:22.952529+00:00 [queued]>
[2024-08-11T12:41:31.980+0000] {taskinstance.py:2306} INFO - Starting attempt 1 of 3
[2024-08-11T12:41:31.995+0000] {taskinstance.py:2330} INFO - Executing <Task(S3KeySensor): is_file_in_s3> on 2024-08-11 12:41:22.952529+00:00
[2024-08-11T12:41:31.998+0000] {standard_task_runner.py:64} INFO - Started process 6150 to run task
[2024-08-11T12:41:32.000+0000] {standard_task_runner.py:90} INFO - Running: ['airflow', 'tasks', 'run', 'Zillow_Analytics_DAG', 'is_file_in_s3', 'manual__2024-08-11T12:41:22.952529+00:00', '--job-id', '58', '--raw', '--subdir', 'DAGS_FOLDER/zillowrapidapi.py', '--cfg-path', '/tmp/tmpxn38wd9e']
[2024-08-11T12:41:32.002+0000] {standard_task_runner.py:91} INFO - Job 58: Subtask is_file_in_s3
[2024-08-11T12:41:32.038+0000] {task_command.py:426} INFO - Running <TaskInstance: Zillow_Analytics_DAG.is_file_in_s3 manual__2024-08-11T12:41:22.952529+00:00 [running]> on host ip-172-31-11-55.ap-south-1.compute.internal
[2024-08-11T12:41:32.113+0000] {taskinstance.py:2648} INFO - Exporting env vars: AIRFLOW_CTX_DAG_EMAIL='vkkr800@gmail.com' AIRFLOW_CTX_DAG_OWNER='airflow' AIRFLOW_CTX_DAG_ID='Zillow_Analytics_DAG' AIRFLOW_CTX_TASK_ID='is_file_in_s3' AIRFLOW_CTX_EXECUTION_DATE='2024-08-11T12:41:22.952529+00:00' AIRFLOW_CTX_TRY_NUMBER='1' AIRFLOW_CTX_DAG_RUN_ID='manual__2024-08-11T12:41:22.952529+00:00'
[2024-08-11T12:41:32.114+0000] {taskinstance.py:430} INFO - ::endgroup::
[2024-08-11T12:41:32.125+0000] {baseoperator.py:400} WARNING - S3KeySensor.execute cannot be called outside TaskInstance!
[2024-08-11T12:41:32.125+0000] {s3.py:118} INFO - Poking for key : s3://zillow-api-third-bucket//home/ubuntu/response_data_11082024124125.json
[2024-08-11T12:41:32.131+0000] {base.py:84} INFO - Using connection ID 'aws_s3_conn' for task execution.
[2024-08-11T12:41:32.131+0000] {connection_wrapper.py:388} INFO - AWS Connection (conn_id='aws_s3_conn', conn_type='aws') credentials retrieved from login and password.
[2024-08-11T12:41:37.465+0000] {s3.py:118} INFO - Poking for key : s3://zillow-api-third-bucket//home/ubuntu/response_data_11082024124125.json
[2024-08-11T12:41:42.475+0000] {s3.py:118} INFO - Poking for key : s3://zillow-api-third-bucket//home/ubuntu/response_data_11082024124125.json
[2024-08-11T12:41:47.484+0000] {s3.py:118} INFO - Poking for key : s3://zillow-api-third-bucket//home/ubuntu/response_data_11082024124125.json
[2024-08-11T12:41:52.495+0000] {s3.py:118} INFO - Poking for key : s3://zillow-api-third-bucket//home/ubuntu/response_data_11082024124125.json
[2024-08-11T12:41:57.503+0000] {s3.py:118} INFO - Poking for key : s3://zillow-api-third-bucket//home/ubuntu/response_data_11082024124125.json
[2024-08-11T12:42:02.511+0000] {s3.py:118} INFO - Poking for key : s3://zillow-api-third-bucket//home/ubuntu/response_data_11082024124125.json
[2024-08-11T12:42:07.522+0000] {s3.py:118} INFO - Poking for key : s3://zillow-api-third-bucket//home/ubuntu/response_data_11082024124125.json
[2024-08-11T12:42:12.530+0000] {s3.py:118} INFO - Poking for key : s3://zillow-api-third-bucket//home/ubuntu/response_data_11082024124125.json
[2024-08-11T12:42:17.541+0000] {s3.py:118} INFO - Poking for key : s3://zillow-api-third-bucket//home/ubuntu/response_data_11082024124125.json
[2024-08-11T12:42:22.549+0000] {s3.py:118} INFO - Poking for key : s3://zillow-api-third-bucket//home/ubuntu/response_data_11082024124125.json
[2024-08-11T12:42:27.559+0000] {s3.py:118} INFO - Poking for key : s3://zillow-api-third-bucket//home/ubuntu/response_data_11082024124125.json
[2024-08-11T12:42:32.569+0000] {s3.py:118} INFO - Poking for key : s3://zillow-api-third-bucket//home/ubuntu/response_data_11082024124125.json
[2024-08-11T12:42:32.577+0000] {taskinstance.py:441} INFO - ::group::Post task execution logs
[2024-08-11T12:42:32.577+0000] {taskinstance.py:2905} ERROR - Task failed with exception
Traceback (most recent call last):
  File "/home/ubuntu/zilloapi/lib/python3.12/site-packages/airflow/models/taskinstance.py", line 465, in _execute_task
    result = _execute_callable(context=context, **execute_callable_kwargs)
             ^^^^^^^^^^^^^^^^^^^^^^^^^^^^^^^^^^^^^^^^^^^^^^^^^^^^^^^^^^^^^
  File "/home/ubuntu/zilloapi/lib/python3.12/site-packages/airflow/models/taskinstance.py", line 432, in _execute_callable
    return execute_callable(context=context, **execute_callable_kwargs)
           ^^^^^^^^^^^^^^^^^^^^^^^^^^^^^^^^^^^^^^^^^^^^^^^^^^^^^^^^^^^^
  File "/home/ubuntu/zilloapi/lib/python3.12/site-packages/airflow/models/baseoperator.py", line 401, in wrapper
    return func(self, *args, **kwargs)
           ^^^^^^^^^^^^^^^^^^^^^^^^^^^
  File "/home/ubuntu/zilloapi/lib/python3.12/site-packages/airflow/providers/amazon/aws/sensors/s3.py", line 189, in execute
    super().execute(context)
  File "/home/ubuntu/zilloapi/lib/python3.12/site-packages/airflow/models/baseoperator.py", line 401, in wrapper
    return func(self, *args, **kwargs)
           ^^^^^^^^^^^^^^^^^^^^^^^^^^^
  File "/home/ubuntu/zilloapi/lib/python3.12/site-packages/airflow/sensors/base.py", line 281, in execute
    raise AirflowSensorTimeout(message)
airflow.exceptions.AirflowSensorTimeout: Sensor has timed out; run duration of 60.45148127799985 seconds exceeds the specified timeout of 60.0.
[2024-08-11T12:42:32.581+0000] {taskinstance.py:1206} INFO - Immediate failure requested. Marking task as FAILED. dag_id=Zillow_Analytics_DAG, task_id=is_file_in_s3, run_id=manual__2024-08-11T12:41:22.952529+00:00, execution_date=20240811T124122, start_date=20240811T124131, end_date=20240811T124232
[2024-08-11T12:42:32.595+0000] {standard_task_runner.py:110} ERROR - Failed to execute job 58 for task is_file_in_s3 (Sensor has timed out; run duration of 60.45148127799985 seconds exceeds the specified timeout of 60.0.; 6150)
[2024-08-11T12:42:32.610+0000] {local_task_job_runner.py:243} INFO - Task exited with return code 1
[2024-08-11T12:42:32.617+0000] {taskinstance.py:3503} INFO - 0 downstream tasks scheduled from follow-on schedule check
[2024-08-11T12:42:32.617+0000] {local_task_job_runner.py:222} INFO - ::endgroup::
