[2024-08-11T12:32:57.228+0000] {local_task_job_runner.py:120} INFO - ::group::Pre task execution logs
[2024-08-11T12:32:57.238+0000] {taskinstance.py:2076} INFO - Dependencies all met for dep_context=non-requeueable deps ti=<TaskInstance: Zillow_Analytics_DAG.is_file_in_s3 manual__2024-08-11T12:32:47.605749+00:00 [queued]>
[2024-08-11T12:32:57.244+0000] {taskinstance.py:2076} INFO - Dependencies all met for dep_context=requeueable deps ti=<TaskInstance: Zillow_Analytics_DAG.is_file_in_s3 manual__2024-08-11T12:32:47.605749+00:00 [queued]>
[2024-08-11T12:32:57.244+0000] {taskinstance.py:2306} INFO - Starting attempt 1 of 3
[2024-08-11T12:32:57.260+0000] {taskinstance.py:2330} INFO - Executing <Task(S3KeySensor): is_file_in_s3> on 2024-08-11 12:32:47.605749+00:00
[2024-08-11T12:32:57.263+0000] {standard_task_runner.py:64} INFO - Started process 6080 to run task
[2024-08-11T12:32:57.266+0000] {standard_task_runner.py:90} INFO - Running: ['airflow', 'tasks', 'run', 'Zillow_Analytics_DAG', 'is_file_in_s3', 'manual__2024-08-11T12:32:47.605749+00:00', '--job-id', '50', '--raw', '--subdir', 'DAGS_FOLDER/zillowrapidapi.py', '--cfg-path', '/tmp/tmpoci0oxex']
[2024-08-11T12:32:57.267+0000] {standard_task_runner.py:91} INFO - Job 50: Subtask is_file_in_s3
[2024-08-11T12:32:57.302+0000] {task_command.py:426} INFO - Running <TaskInstance: Zillow_Analytics_DAG.is_file_in_s3 manual__2024-08-11T12:32:47.605749+00:00 [running]> on host ip-172-31-11-55.ap-south-1.compute.internal
[2024-08-11T12:32:57.377+0000] {taskinstance.py:2648} INFO - Exporting env vars: AIRFLOW_CTX_DAG_EMAIL='vkkr800@gmail.com' AIRFLOW_CTX_DAG_OWNER='airflow' AIRFLOW_CTX_DAG_ID='Zillow_Analytics_DAG' AIRFLOW_CTX_TASK_ID='is_file_in_s3' AIRFLOW_CTX_EXECUTION_DATE='2024-08-11T12:32:47.605749+00:00' AIRFLOW_CTX_TRY_NUMBER='1' AIRFLOW_CTX_DAG_RUN_ID='manual__2024-08-11T12:32:47.605749+00:00'
[2024-08-11T12:32:57.378+0000] {taskinstance.py:430} INFO - ::endgroup::
[2024-08-11T12:32:57.388+0000] {baseoperator.py:400} WARNING - S3KeySensor.execute cannot be called outside TaskInstance!
[2024-08-11T12:32:57.389+0000] {s3.py:118} INFO - Poking for key : s3://zillow-api-third-bucket//home/ubuntu/response_data_11082024123250.json
[2024-08-11T12:32:57.393+0000] {base.py:84} INFO - Using connection ID 'aws_s3_conn' for task execution.
[2024-08-11T12:32:57.394+0000] {connection_wrapper.py:388} INFO - AWS Connection (conn_id='aws_s3_conn', conn_type='aws') credentials retrieved from login and password.
[2024-08-11T12:33:02.737+0000] {s3.py:118} INFO - Poking for key : s3://zillow-api-third-bucket//home/ubuntu/response_data_11082024123250.json
[2024-08-11T12:33:07.747+0000] {s3.py:118} INFO - Poking for key : s3://zillow-api-third-bucket//home/ubuntu/response_data_11082024123250.json
[2024-08-11T12:33:12.758+0000] {s3.py:118} INFO - Poking for key : s3://zillow-api-third-bucket//home/ubuntu/response_data_11082024123250.json
[2024-08-11T12:33:17.767+0000] {s3.py:118} INFO - Poking for key : s3://zillow-api-third-bucket//home/ubuntu/response_data_11082024123250.json
[2024-08-11T12:33:22.777+0000] {s3.py:118} INFO - Poking for key : s3://zillow-api-third-bucket//home/ubuntu/response_data_11082024123250.json
[2024-08-11T12:33:27.785+0000] {s3.py:118} INFO - Poking for key : s3://zillow-api-third-bucket//home/ubuntu/response_data_11082024123250.json
[2024-08-11T12:33:32.795+0000] {s3.py:118} INFO - Poking for key : s3://zillow-api-third-bucket//home/ubuntu/response_data_11082024123250.json
[2024-08-11T12:33:37.803+0000] {s3.py:118} INFO - Poking for key : s3://zillow-api-third-bucket//home/ubuntu/response_data_11082024123250.json
[2024-08-11T12:33:42.813+0000] {s3.py:118} INFO - Poking for key : s3://zillow-api-third-bucket//home/ubuntu/response_data_11082024123250.json
[2024-08-11T12:33:47.822+0000] {s3.py:118} INFO - Poking for key : s3://zillow-api-third-bucket//home/ubuntu/response_data_11082024123250.json
[2024-08-11T12:33:52.830+0000] {s3.py:118} INFO - Poking for key : s3://zillow-api-third-bucket//home/ubuntu/response_data_11082024123250.json
[2024-08-11T12:33:57.840+0000] {s3.py:118} INFO - Poking for key : s3://zillow-api-third-bucket//home/ubuntu/response_data_11082024123250.json
[2024-08-11T12:33:57.849+0000] {taskinstance.py:441} INFO - ::group::Post task execution logs
[2024-08-11T12:33:57.849+0000] {taskinstance.py:2905} ERROR - Task failed with exception
Traceback (most recent call last):
  File "/home/ubuntu/zilloapi/lib/python3.12/site-packages/airflow/models/taskinstance.py", line 465, in _execute_task
    result = _execute_callable(context=context, **execute_callable_kwargs)
             ^^^^^^^^^^^^^^^^^^^^^^^^^^^^^^^^^^^^^^^^^^^^^^^^^^^^^^^^^^^^^
  File "/home/ubuntu/zilloapi/lib/python3.12/site-packages/airflow/models/taskinstance.py", line 432, in _execute_callable
    return execute_callable(context=context, **execute_callable_kwargs)
           ^^^^^^^^^^^^^^^^^^^^^^^^^^^^^^^^^^^^^^^^^^^^^^^^^^^^^^^^^^^^
  File "/home/ubuntu/zilloapi/lib/python3.12/site-packages/airflow/models/baseoperator.py", line 401, in wrapper
    return func(self, *args, **kwargs)
           ^^^^^^^^^^^^^^^^^^^^^^^^^^^
  File "/home/ubuntu/zilloapi/lib/python3.12/site-packages/airflow/providers/amazon/aws/sensors/s3.py", line 189, in execute
    super().execute(context)
  File "/home/ubuntu/zilloapi/lib/python3.12/site-packages/airflow/models/baseoperator.py", line 401, in wrapper
    return func(self, *args, **kwargs)
           ^^^^^^^^^^^^^^^^^^^^^^^^^^^
  File "/home/ubuntu/zilloapi/lib/python3.12/site-packages/airflow/sensors/base.py", line 281, in execute
    raise AirflowSensorTimeout(message)
airflow.exceptions.AirflowSensorTimeout: Sensor has timed out; run duration of 60.460019280997585 seconds exceeds the specified timeout of 60.0.
[2024-08-11T12:33:57.852+0000] {taskinstance.py:1206} INFO - Immediate failure requested. Marking task as FAILED. dag_id=Zillow_Analytics_DAG, task_id=is_file_in_s3, run_id=manual__2024-08-11T12:32:47.605749+00:00, execution_date=20240811T123247, start_date=20240811T123257, end_date=20240811T123357
[2024-08-11T12:33:57.866+0000] {standard_task_runner.py:110} ERROR - Failed to execute job 50 for task is_file_in_s3 (Sensor has timed out; run duration of 60.460019280997585 seconds exceeds the specified timeout of 60.0.; 6080)
[2024-08-11T12:33:57.900+0000] {local_task_job_runner.py:243} INFO - Task exited with return code 1
[2024-08-11T12:33:57.908+0000] {taskinstance.py:3503} INFO - 0 downstream tasks scheduled from follow-on schedule check
[2024-08-11T12:33:57.909+0000] {local_task_job_runner.py:222} INFO - ::endgroup::
